Workbook
Name CareCosts: Constants!$W$4:$X$10
Name CCBHourlyRate: Constants!$R$4
Name CCBMaxHours: Constants!$R$3
Name CCBThreshold: Constants!$R$5
Name CCBThresholdModifier: Constants!$R$6
Name CCRMax: Constants!$R$8
Name CCRRate: Constants!$R$7
Name EmployeeSuper: Constants!$K$4:$L$7
Name EmployerSuper: Constants!$H$4:$I$13
Name FixedTax: Constants!$A$4:$B$8
Name HELP: Constants!$E$4:$F$12
Name Holidays: Constants!$U$3:$U$14
Name IncomeThreshold: Constants!$A$4:$A$8
Name Rooms: Constants!$N$4:$O$7
Name SaturdayPenalty: Constants!$X$11
Name TaxPercentage: Constants!$A$4:$C$8

Sheet Student Details
A1: BISM7202 Assignment - Semester 1, 2018
A2: Sunshine Childcare
A3: Assignment Template
A5: Documentation
A7: Student Information | F7: Note: Student numbers are eight digits and do not begin with an 's'.
A8: Student ID | C8: Family Name | D8: Given Name
A9: 45238952 | C9: Kyaw | D9: Pyae Phyo
A11: Assumptions
A13: Replace all pre-defined name ranges that were linking to another workbook with new name ranges. Child birthday is calculated in pre-birthday cost. Advance filtering criteria apply to both the database and the database function table (total,min,avg,max). Average Weekdays from 2019 Planner is constant for throughout the year. (No reduction for holidays)
A27: Tip: To switch to the next line in one cell, use the key combination 'Alt+Enter'.

Sheet Constants
A2: Tax Table | E2: HELP Repayment Table | H2: Employer Superannuation Contribution | K2: Employee Superannuation Contribution | N2: Child Care Rooms | Q2: Family Child Care Info | T2: Holidays | W2: Child Care Costs
A3: Income | B3: Fixed Tax | C3: Tax Percentage | E3: Repayable Income | F3: Repayment Rate | H3: Position | I3: Percentage | K3: Age | L3: Percentage | N3: Age | O3: Rooms | Q3: CCB Max Hours | R3: 50 | T3: New Year's Day | U3: 43101 | W3: Age | X3: Day Rate
A4: 0 | B4: 0 | C4: 0 | E4: 55874 | F4: 0.04 | H4: Director | I4: 0.125 | K4: 25 | L4: 0.025 | N4: 0 | O4: Platypus Room | Q4: CCB Hourly Rate | R4: 0.719 | T4: Australia Day | U4: 43126 | W4: 0 | X4: 120
A5: 18200 | B5: 0 | C5: 0.19 | E5: 62239 | F5: 0.045 | H5: Deputy Director | I5: 0.12 | K5: 35 | L5: 0.03 | N5: 2 | O5: Emu Room | Q5: CCB Threshold | R5: 45114 | T5: Good Friday | U5: 43189 | W5: 1 | X5: 110
A6: 37000 | B6: 3572 | C6: 0.325 | E6: 68603 | F6: 0.05 | H6: Senior Accountant | I6: 0.115 | K6: 45 | L6: 0.035 | N6: 3 | O6: Koala Room | Q6: CCB Threshold Modifier | R6: 6.5e-06 | T6: Easter Saturday | U6: 43190 | W6: 2 | X6: 105
A7: 87000 | B7: 19822 | C7: 0.37 | E7: 72208 | F7: 0.055 | H7: Accountant | I7: 0.11 | K7: 50 | L7: 0.05 | N7: 4 | O7: Kangaroo Room | Q7: CCR Rate | R7: 0.5 | T7: Easter Sunday | U7: 43191 | W7: 3 | X7: 90
A8: 180000 | B8: 54232 | C8: 0.45 | E8: 77619 | F8: 0.06 | H8: Chef | I8: 0.1 | Q8: CCR Max | R8: 7613 | T8: Easter Monday | U8: 43192 | W8: 4 | X8: 85
E9: 84063 | F9: 0.065 | H9: Assistant Chef | I9: 0.095 | T9: Anzac Day | U9: 43215 | W9: 5 | X9: 80
E10: 88487 | F10: 0.07 | H10: Child Care Leader | I10: 0.1 | T10: Labour Day | U10: 43227 | W10: 6 | X10: Not Allowed
E11: 97378 | F11: 0.075 | H11: Child Care Worker | I11: 0.095 | T11: Ekka Wednesday | U11: 43327 | W11: Saturday Penalty | X11: 10
E12: 103766 | F12: 0.08 | H12: Junior Child Care Worker | I12: 0.095 | T12: Queen's Birthday | U12: 43374
H13: Custodial Engineer | I13: 0.095 | T13: Christmas Day | U13: 43459
T14: Boxing Day | U14: 43460

Sheet Employees & Volunteers
A1: Sunshine Employees & Volunteers
A2: First Name | B2: Last Name | C2: Gender | D2: Position | E2: HELP Debt | F2: DOB | G2: Annual Income | H2: Employer Superannuation | I2: Employee Superannuation | J2: Annual Tax | K2: HELP Withheld | L2: Net Salary
A3: Jorja | B3: Arnott | C3: Female | D3: Volunteer Carer | F3: 23303 | G3: 0 | H3: =G3* IF(D3<>"Volunteer Carer", VLOOKUP(D3,EmployerSuper,2,FALSE),0) -> 0 | I3: =IF(AND(D3<>"Volunteer Carer",YEARFRAC(DATE(2017,12,31),F3)>=25), VLOOKUP(YEARFRAC(DATE(2017,12,31),F3),EmployeeSuper,2,TRUE)*(G3-J3),0) -> 0 | J3: =VLOOKUP(G3,FixedTax,2,TRUE) +((G3-VLOOKUP(G3,IncomeThreshold,1,TRUE)) * VLOOKUP(G3,TaxPercentage,3,TRUE)) -> 0 | K3: =IF(AND(G3>55874,E3=TRUE), VLOOKUP(G3,HELP,2,TRUE), 0) *G3 -> 0 | L3: =(G3+H3)-(I3+J3) -> 0
A4: Xavier | B4: Benstead | C4: Male | D4: Custodial Engineer | F4: 23422 | G4: 35423 | H4: =G4* IF(D4<>"Volunteer Carer", VLOOKUP(D4,EmployerSuper,2,FALSE),0) -> 3365.185 | I4: =IF(AND(D4<>"Volunteer Carer",YEARFRAC(DATE(2017,12,31),F4)>=25), VLOOKUP(YEARFRAC(DATE(2017,12,31),F4),EmployeeSuper,2,TRUE)*(G4-J4),0) -> 1607.5315 | J4: =VLOOKUP(G4,FixedTax,2,TRUE) +((G4-VLOOKUP(G4,IncomeThreshold,1,TRUE)) * VLOOKUP(G4,TaxPercentage,3,TRUE)) -> 3272.37 | K4: =IF(AND(G4>55874,E4=TRUE), VLOOKUP(G4,HELP,2,TRUE), 0) *G4 -> 0 | L4: =(G4+H4)-(I4+J4) -> 33908.283
A5: Abby | B5: Dennis | C5: Female | D5: Volunteer Carer | F5: 26560 | G5: 0 | H5: =G5* IF(D5<>"Volunteer Carer", VLOOKUP(D5,EmployerSuper,2,FALSE),0) -> 0 | I5: =IF(AND(D5<>"Volunteer Carer",YEARFRAC(DATE(2017,12,31),F5)>=25), VLOOKUP(YEARFRAC(DATE(2017,12,31),F5),EmployeeSuper,2,TRUE)*(G5-J5),0) -> 0 | J5: =VLOOKUP(G5,FixedTax,2,TRUE) +((G5-VLOOKUP(G5,IncomeThreshold,1,TRUE)) * VLOOKUP(G5,TaxPercentage,3,TRUE)) -> 0 | K5: =IF(AND(G5>55874,E5=TRUE), VLOOKUP(G5,HELP,2,TRUE), 0) *G5 -> 0 | L5: =(G5+H5)-(I5+J5) -> 0
A6: Isaac | B6: Foelsche | C6: Male | D6: Custodial Engineer | F6: 27695 | G6: 35423 | H6: =G6* IF(D6<>"Volunteer Carer", VLOOKUP(D6,EmployerSuper,2,FALSE),0) -> 3365.185 | I6: =IF(AND(D6<>"Volunteer Carer",YEARFRAC(DATE(2017,12,31),F6)>=25), VLOOKUP(YEARFRAC(DATE(2017,12,31),F6),EmployeeSuper,2,TRUE)*(G6-J6),0) -> 964.5189 | J6: =VLOOKUP(G6,FixedTax,2,TRUE) +((G6-VLOOKUP(G6,IncomeThreshold,1,TRUE)) * VLOOKUP(G6,TaxPercentage,3,TRUE)) -> 3272.37 | K6: =IF(AND(G6>55874,E6=TRUE), VLOOKUP(G6,HELP,2,TRUE), 0) *G6 -> 0 | L6: =(G6+H6)-(I6+J6) -> 34551.296
A7: Claudia | B7: Philp | C7: Female | D7: Director | E7: TRUE | F7: 28843 | G7: 89534 | H7: =G7* IF(D7<>"Volunteer Carer", VLOOKUP(D7,EmployerSuper,2,FALSE),0) -> 11191.75 | I7: =IF(AND(D7<>"Volunteer Carer",YEARFRAC(DATE(2017,12,31),F7)>=25), VLOOKUP(YEARFRAC(DATE(2017,12,31),F7),EmployeeSuper,2,TRUE)*(G7-J7),0) -> 2063.2326 | J7: =VLOOKUP(G7,FixedTax,2,TRUE) +((G7-VLOOKUP(G7,IncomeThreshold,1,TRUE)) * VLOOKUP(G7,TaxPercentage,3,TRUE)) -> 20759.58 | K7: =IF(AND(G7>55874,E7=TRUE), VLOOKUP(G7,HELP,2,TRUE), 0) *G7 -> 6267.38 | L7: =(G7+H7)-(I7+J7) -> 77902.937
A8: Ellie | B8: Watson | C8: Female | D8: Child Care Leader | F8: 29039 | G8: 48310 | H8: =G8* IF(D8<>"Volunteer Carer", VLOOKUP(D8,EmployerSuper,2,FALSE),0) -> 4831 | I8: =IF(AND(D8<>"Volunteer Carer",YEARFRAC(DATE(2017,12,31),F8)>=25), VLOOKUP(YEARFRAC(DATE(2017,12,31),F8),EmployeeSuper,2,TRUE)*(G8-J8),0) -> 1231.8675 | J8: =VLOOKUP(G8,FixedTax,2,TRUE) +((G8-VLOOKUP(G8,IncomeThreshold,1,TRUE)) * VLOOKUP(G8,TaxPercentage,3,TRUE)) -> 7247.75 | K8: =IF(AND(G8>55874,E8=TRUE), VLOOKUP(G8,HELP,2,TRUE), 0) *G8 -> 0 | L8: =(G8+H8)-(I8+J8) -> 44661.382
A9: Christian | B9: Tancred | C9: Male | D9: Child Care Leader | E9: TRUE | F9: 29612 | G9: 56989 | H9: =G9* IF(D9<>"Volunteer Carer", VLOOKUP(D9,EmployerSuper,2,FALSE),0) -> 5698.9 | I9: =IF(AND(D9<>"Volunteer Carer",YEARFRAC(DATE(2017,12,31),F9)>=25), VLOOKUP(YEARFRAC(DATE(2017,12,31),F9),EmployeeSuper,2,TRUE)*(G9-J9),0) -> 1407.6172 | J9: =VLOOKUP(G9,FixedTax,2,TRUE) +((G9-VLOOKUP(G9,IncomeThreshold,1,TRUE)) * VLOOKUP(G9,TaxPercentage,3,TRUE)) -> 10068.425 | K9: =IF(AND(G9>55874,E9=TRUE), VLOOKUP(G9,HELP,2,TRUE), 0) *G9 -> 2279.56 | L9: =(G9+H9)-(I9+J9) -> 51211.858
A10: Madeline | B10: Strachan | C10: Female | D10: Child Care Leader | F10: 30078 | G10: 52487 | H10: =G10* IF(D10<>"Volunteer Carer", VLOOKUP(D10,EmployerSuper,2,FALSE),0) -> 5248.7 | I10: =IF(AND(D10<>"Volunteer Carer",YEARFRAC(DATE(2017,12,31),F10)>=25), VLOOKUP(YEARFRAC(DATE(2017,12,31),F10),EmployeeSuper,2,TRUE)*(G10-J10),0) -> 1316.4517 | J10: =VLOOKUP(G10,FixedTax,2,TRUE) +((G10-VLOOKUP(G10,IncomeThreshold,1,TRUE)) * VLOOKUP(G10,TaxPercentage,3,TRUE)) -> 8605.275 | K10: =IF(AND(G10>55874,E10=TRUE), VLOOKUP(G10,HELP,2,TRUE), 0) *G10 -> 0 | L10: =(G10+H10)-(I10+J10) -> 47813.973
A11: Taylah | B11: McMahon | C11: Female | D11: Child Care Leader | E11: TRUE | F11: 30386 | G11: 48310 | H11: =G11* IF(D11<>"Volunteer Carer", VLOOKUP(D11,EmployerSuper,2,FALSE),0) -> 4831 | I11: =IF(AND(D11<>"Volunteer Carer",YEARFRAC(DATE(2017,12,31),F11)>=25), VLOOKUP(YEARFRAC(DATE(2017,12,31),F11),EmployeeSuper,2,TRUE)*(G11-J11),0) -> 1026.5563 | J11: =VLOOKUP(G11,FixedTax,2,TRUE) +((G11-VLOOKUP(G11,IncomeThreshold,1,TRUE)) * VLOOKUP(G11,TaxPercentage,3,TRUE)) -> 7247.75 | K11: =IF(AND(G11>55874,E11=TRUE), VLOOKUP(G11,HELP,2,TRUE), 0) *G11 -> 0 | L11: =(G11+H11)-(I11+J11) -> 44866.694
A12: Sofia | B12: Goold-Adams | C12: Female | D12: Deputy Director | E12: TRUE | F12: 30545 | G12: 74879 | H12: =G12* IF(D12<>"Volunteer Carer", VLOOKUP(D12,EmployerSuper,2,FALSE),0) -> 8985.48 | I12: =IF(AND(D12<>"Volunteer Carer",YEARFRAC(DATE(2017,12,31),F12)>=25), VLOOKUP(YEARFRAC(DATE(2017,12,31),F12),EmployeeSuper,2,TRUE)*(G12-J12),0) -> 1474.9081 | J12: =VLOOKUP(G12,FixedTax,2,TRUE) +((G12-VLOOKUP(G12,IncomeThreshold,1,TRUE)) * VLOOKUP(G12,TaxPercentage,3,TRUE)) -> 15882.675 | K12: =IF(AND(G12>55874,E12=TRUE), VLOOKUP(G12,HELP,2,TRUE), 0) *G12 -> 4118.345 | L12: =(G12+H12)-(I12+J12) -> 66506.897
A13: Scarlett | B13: Seager | C13: Female | D13: Child Care Worker | F13: 31294 | G13: 40750 | H13: =G13* IF(D13<>"Volunteer Carer", VLOOKUP(D13,EmployerSuper,2,FALSE),0) -> 3871.25 | I13: =IF(AND(D13<>"Volunteer Carer",YEARFRAC(DATE(2017,12,31),F13)>=25), VLOOKUP(YEARFRAC(DATE(2017,12,31),F13),EmployeeSuper,2,TRUE)*(G13-J13),0) -> 898.98125 | J13: =VLOOKUP(G13,FixedTax,2,TRUE) +((G13-VLOOKUP(G13,IncomeThreshold,1,TRUE)) * VLOOKUP(G13,TaxPercentage,3,TRUE)) -> 4790.75 | K13: =IF(AND(G13>55874,E13=TRUE), VLOOKUP(G13,HELP,2,TRUE), 0) *G13 -> 0 | L13: =(G13+H13)-(I13+J13) -> 38931.519
A14: Sam | B14: Roth | C14: Female | D14: Volunteer Carer | E14: TRUE | F14: 32296 | G14: 0 | H14: =G14* IF(D14<>"Volunteer Carer", VLOOKUP(D14,EmployerSuper,2,FALSE),0) -> 0 | I14: =IF(AND(D14<>"Volunteer Carer",YEARFRAC(DATE(2017,12,31),F14)>=25), VLOOKUP(YEARFRAC(DATE(2017,12,31),F14),EmployeeSuper,2,TRUE)*(G14-J14),0) -> 0 | J14: =VLOOKUP(G14,FixedTax,2,TRUE) +((G14-VLOOKUP(G14,IncomeThreshold,1,TRUE)) * VLOOKUP(G14,TaxPercentage,3,TRUE)) -> 0 | K14: =IF(AND(G14>55874,E14=TRUE), VLOOKUP(G14,HELP,2,TRUE), 0) *G14 -> 0 | L14: =(G14+H14)-(I14+J14) -> 0
A15: Rachel | B15: Mansergh | C15: Female | D15: Senior Accountant | E15: TRUE | F15: 32405 | G15: 68423 | H15: =G15* IF(D15<>"Volunteer Carer", VLOOKUP(D15,EmployerSuper,2,FALSE),0) -> 7868.645 | I15: =IF(AND(D15<>"Volunteer Carer",YEARFRAC(DATE(2017,12,31),F15)>=25), VLOOKUP(YEARFRAC(DATE(2017,12,31),F15),EmployeeSuper,2,TRUE)*(G15-J15),0) -> 1365.9631 | J15: =VLOOKUP(G15,FixedTax,2,TRUE) +((G15-VLOOKUP(G15,IncomeThreshold,1,TRUE)) * VLOOKUP(G15,TaxPercentage,3,TRUE)) -> 13784.475 | K15: =IF(AND(G15>55874,E15=TRUE), VLOOKUP(G15,HELP,2,TRUE), 0) *G15 -> 3079.035 | L15: =(G15+H15)-(I15+J15) -> 61141.207
A16: Nate | B16: Marian | C16: Male | D16: Child Care Worker | F16: 32481 | G16: 40750 | H16: =G16* IF(D16<>"Volunteer Carer", VLOOKUP(D16,EmployerSuper,2,FALSE),0) -> 3871.25 | I16: =IF(AND(D16<>"Volunteer Carer",YEARFRAC(DATE(2017,12,31),F16)>=25), VLOOKUP(YEARFRAC(DATE(2017,12,31),F16),EmployeeSuper,2,TRUE)*(G16-J16),0) -> 898.98125 | J16: =VLOOKUP(G16,FixedTax,2,TRUE) +((G16-VLOOKUP(G16,IncomeThreshold,1,TRUE)) * VLOOKUP(G16,TaxPercentage,3,TRUE)) -> 4790.75 | K16: =IF(AND(G16>55874,E16=TRUE), VLOOKUP(G16,HELP,2,TRUE), 0) *G16 -> 0 | L16: =(G16+H16)-(I16+J16) -> 38931.519
A17: Alex | B17: Dakin | C17: Female | D17: Child Care Leader | E17: TRUE | F17: 32561 | G17: 56989 | H17: =G17* IF(D17<>"Volunteer Carer", VLOOKUP(D17,EmployerSuper,2,FALSE),0) -> 5698.9 | I17: =IF(AND(D17<>"Volunteer Carer",YEARFRAC(DATE(2017,12,31),F17)>=25), VLOOKUP(YEARFRAC(DATE(2017,12,31),F17),EmployeeSuper,2,TRUE)*(G17-J17),0) -> 1173.0144 | J17: =VLOOKUP(G17,FixedTax,2,TRUE) +((G17-VLOOKUP(G17,IncomeThreshold,1,TRUE)) * VLOOKUP(G17,TaxPercentage,3,TRUE)) -> 10068.425 | K17: =IF(AND(G17>55874,E17=TRUE), VLOOKUP(G17,HELP,2,TRUE), 0) *G17 -> 2279.56 | L17: =(G17+H17)-(I17+J17) -> 51446.461
A18: Isaac | B18: Dumaresq | C18: Male | D18: Chef | E18: TRUE | F18: 33064 | G18: 54326 | H18: =G18* IF(D18<>"Volunteer Carer", VLOOKUP(D18,EmployerSuper,2,FALSE),0) -> 5432.6 | I18: =IF(AND(D18<>"Volunteer Carer",YEARFRAC(DATE(2017,12,31),F18)>=25), VLOOKUP(YEARFRAC(DATE(2017,12,31),F18),EmployeeSuper,2,TRUE)*(G18-J18),0) -> 1128.0763 | J18: =VLOOKUP(G18,FixedTax,2,TRUE) +((G18-VLOOKUP(G18,IncomeThreshold,1,TRUE)) * VLOOKUP(G18,TaxPercentage,3,TRUE)) -> 9202.95 | K18: =IF(AND(G18>55874,E18=TRUE), VLOOKUP(G18,HELP,2,TRUE), 0) *G18 -> 0 | L18: =(G18+H18)-(I18+J18) -> 49427.574
A19: Indiana | B19: Gask | C19: Female | D19: Chef | E19: TRUE | F19: 33423 | G19: 54326 | H19: =G19* IF(D19<>"Volunteer Carer", VLOOKUP(D19,EmployerSuper,2,FALSE),0) -> 5432.6 | I19: =IF(AND(D19<>"Volunteer Carer",YEARFRAC(DATE(2017,12,31),F19)>=25), VLOOKUP(YEARFRAC(DATE(2017,12,31),F19),EmployeeSuper,2,TRUE)*(G19-J19),0) -> 1128.0763 | J19: =VLOOKUP(G19,FixedTax,2,TRUE) +((G19-VLOOKUP(G19,IncomeThreshold,1,TRUE)) * VLOOKUP(G19,TaxPercentage,3,TRUE)) -> 9202.95 | K19: =IF(AND(G19>55874,E19=TRUE), VLOOKUP(G19,HELP,2,TRUE), 0) *G19 -> 0 | L19: =(G19+H19)-(I19+J19) -> 49427.574
A20: Ryan | B20: Loch | C20: Male | D20: Child Care Worker | E20: TRUE | F20: 33847 | G20: 40750 | H20: =G20* IF(D20<>"Volunteer Carer", VLOOKUP(D20,EmployerSuper,2,FALSE),0) -> 3871.25 | I20: =IF(AND(D20<>"Volunteer Carer",YEARFRAC(DATE(2017,12,31),F20)>=25), VLOOKUP(YEARFRAC(DATE(2017,12,31),F20),EmployeeSuper,2,TRUE)*(G20-J20),0) -> 898.98125 | J20: =VLOOKUP(G20,FixedTax,2,TRUE) +((G20-VLOOKUP(G20,IncomeThreshold,1,TRUE)) * VLOOKUP(G20,TaxPercentage,3,TRUE)) -> 4790.75 | K20: =IF(AND(G20>55874,E20=TRUE), VLOOKUP(G20,HELP,2,TRUE), 0) *G20 -> 0 | L20: =(G20+H20)-(I20+J20) -> 38931.519
A21: Alice | B21: Crawley | C21: Female | D21: Assistant Chef | E21: TRUE | F21: 33906 | G21: 43448 | H21: =G21* IF(D21<>"Volunteer Carer", VLOOKUP(D21,EmployerSuper,2,FALSE),0) -> 4127.56 | I21: =IF(AND(D21<>"Volunteer Carer",YEARFRAC(DATE(2017,12,31),F21)>=25), VLOOKUP(YEARFRAC(DATE(2017,12,31),F21),EmployeeSuper,2,TRUE)*(G21-J21),0) -> 944.51 | J21: =VLOOKUP(G21,FixedTax,2,TRUE) +((G21-VLOOKUP(G21,IncomeThreshold,1,TRUE)) * VLOOKUP(G21,TaxPercentage,3,TRUE)) -> 5667.6 | K21: =IF(AND(G21>55874,E21=TRUE), VLOOKUP(G21,HELP,2,TRUE), 0) *G21 -> 0 | L21: =(G21+H21)-(I21+J21) -> 40963.45
A22: Mitchell | B22: Grimley | C22: Male | D22: Assistant Chef | E22: TRUE | F22: 34021 | G22: 43448 | H22: =G22* IF(D22<>"Volunteer Carer", VLOOKUP(D22,EmployerSuper,2,FALSE),0) -> 4127.56 | I22: =IF(AND(D22<>"Volunteer Carer",YEARFRAC(DATE(2017,12,31),F22)>=25), VLOOKUP(YEARFRAC(DATE(2017,12,31),F22),EmployeeSuper,2,TRUE)*(G22-J22),0) -> 0 | J22: =VLOOKUP(G22,FixedTax,2,TRUE) +((G22-VLOOKUP(G22,IncomeThreshold,1,TRUE)) * VLOOKUP(G22,TaxPercentage,3,TRUE)) -> 5667.6 | K22: =IF(AND(G22>55874,E22=TRUE), VLOOKUP(G22,HELP,2,TRUE), 0) *G22 -> 0 | L22: =(G22+H22)-(I22+J22) -> 41907.96
A23: Maddison | B23: Stump | C23: Female | D23: Junior Child Care Worker | F23: 34243 | G23: 35862 | H23: =G23* IF(D23<>"Volunteer Carer", VLOOKUP(D23,EmployerSuper,2,FALSE),0) -> 3406.89 | I23: =IF(AND(D23<>"Volunteer Carer",YEARFRAC(DATE(2017,12,31),F23)>=25), VLOOKUP(YEARFRAC(DATE(2017,12,31),F23),EmployeeSuper,2,TRUE)*(G23-J23),0) -> 0 | J23: =VLOOKUP(G23,FixedTax,2,TRUE) +((G23-VLOOKUP(G23,IncomeThreshold,1,TRUE)) * VLOOKUP(G23,TaxPercentage,3,TRUE)) -> 3355.78 | K23: =IF(AND(G23>55874,E23=TRUE), VLOOKUP(G23,HELP,2,TRUE), 0) *G23 -> 0 | L23: =(G23+H23)-(I23+J23) -> 35913.11
A24: Mason | B24: Train | C24: Male | D24: Child Care Worker | F24: 34608 | G24: 45876 | H24: =G24* IF(D24<>"Volunteer Carer", VLOOKUP(D24,EmployerSuper,2,FALSE),0) -> 4358.22 | I24: =IF(AND(D24<>"Volunteer Carer",YEARFRAC(DATE(2017,12,31),F24)>=25), VLOOKUP(YEARFRAC(DATE(2017,12,31),F24),EmployeeSuper,2,TRUE)*(G24-J24),0) -> 0 | J24: =VLOOKUP(G24,FixedTax,2,TRUE) +((G24-VLOOKUP(G24,IncomeThreshold,1,TRUE)) * VLOOKUP(G24,TaxPercentage,3,TRUE)) -> 6456.7 | K24: =IF(AND(G24>55874,E24=TRUE), VLOOKUP(G24,HELP,2,TRUE), 0) *G24 -> 0 | L24: =(G24+H24)-(I24+J24) -> 43777.52
A25: Ashton | B25: Bethel | C25: Male | D25: Accountant | E25: TRUE | F25: 34806 | G25: 55232 | H25: =G25* IF(D25<>"Volunteer Carer", VLOOKUP(D25,EmployerSuper,2,FALSE),0) -> 6075.52 | I25: =IF(AND(D25<>"Volunteer Carer",YEARFRAC(DATE(2017,12,31),F25)>=25), VLOOKUP(YEARFRAC(DATE(2017,12,31),F25),EmployeeSuper,2,TRUE)*(G25-J25),0) -> 0 | J25: =VLOOKUP(G25,FixedTax,2,TRUE) +((G25-VLOOKUP(G25,IncomeThreshold,1,TRUE)) * VLOOKUP(G25,TaxPercentage,3,TRUE)) -> 9497.4 | K25: =IF(AND(G25>55874,E25=TRUE), VLOOKUP(G25,HELP,2,TRUE), 0) *G25 -> 0 | L25: =(G25+H25)-(I25+J25) -> 51810.12
A26: Harry | B26: Lutwyche | C26: Male | D26: Volunteer Carer | E26: TRUE | F26: 35031 | G26: 0 | H26: =G26* IF(D26<>"Volunteer Carer", VLOOKUP(D26,EmployerSuper,2,FALSE),0) -> 0 | I26: =IF(AND(D26<>"Volunteer Carer",YEARFRAC(DATE(2017,12,31),F26)>=25), VLOOKUP(YEARFRAC(DATE(2017,12,31),F26),EmployeeSuper,2,TRUE)*(G26-J26),0) -> 0 | J26: =VLOOKUP(G26,FixedTax,2,TRUE) +((G26-VLOOKUP(G26,IncomeThreshold,1,TRUE)) * VLOOKUP(G26,TaxPercentage,3,TRUE)) -> 0 | K26: =IF(AND(G26>55874,E26=TRUE), VLOOKUP(G26,HELP,2,TRUE), 0) *G26 -> 0 | L26: =(G26+H26)-(I26+J26) -> 0
A27: Victoria | B27: Lamond | C27: Female | D27: Junior Child Care Worker | F27: 35105 | G27: 35862 | H27: =G27* IF(D27<>"Volunteer Carer", VLOOKUP(D27,EmployerSuper,2,FALSE),0) -> 3406.89 | I27: =IF(AND(D27<>"Volunteer Carer",YEARFRAC(DATE(2017,12,31),F27)>=25), VLOOKUP(YEARFRAC(DATE(2017,12,31),F27),EmployeeSuper,2,TRUE)*(G27-J27),0) -> 0 | J27: =VLOOKUP(G27,FixedTax,2,TRUE) +((G27-VLOOKUP(G27,IncomeThreshold,1,TRUE)) * VLOOKUP(G27,TaxPercentage,3,TRUE)) -> 3355.78 | K27: =IF(AND(G27>55874,E27=TRUE), VLOOKUP(G27,HELP,2,TRUE), 0) *G27 -> 0 | L27: =(G27+H27)-(I27+J27) -> 35913.11
A28: Mariam | B28: Betts | C28: Female | D28: Volunteer Carer | E28: TRUE | F28: 35745 | G28: 0 | H28: =G28* IF(D28<>"Volunteer Carer", VLOOKUP(D28,EmployerSuper,2,FALSE),0) -> 0 | I28: =IF(AND(D28<>"Volunteer Carer",YEARFRAC(DATE(2017,12,31),F28)>=25), VLOOKUP(YEARFRAC(DATE(2017,12,31),F28),EmployeeSuper,2,TRUE)*(G28-J28),0) -> 0 | J28: =VLOOKUP(G28,FixedTax,2,TRUE) +((G28-VLOOKUP(G28,IncomeThreshold,1,TRUE)) * VLOOKUP(G28,TaxPercentage,3,TRUE)) -> 0 | K28: =IF(AND(G28>55874,E28=TRUE), VLOOKUP(G28,HELP,2,TRUE), 0) *G28 -> 0 | L28: =(G28+H28)-(I28+J28) -> 0
A29: Sam | B29: Wrenfordsley | C29: Female | D29: Junior Child Care Worker | E29: TRUE | F29: 35838 | G29: 35862 | H29: =G29* IF(D29<>"Volunteer Carer", VLOOKUP(D29,EmployerSuper,2,FALSE),0) -> 3406.89 | I29: =IF(AND(D29<>"Volunteer Carer",YEARFRAC(DATE(2017,12,31),F29)>=25), VLOOKUP(YEARFRAC(DATE(2017,12,31),F29),EmployeeSuper,2,TRUE)*(G29-J29),0) -> 0 | J29: =VLOOKUP(G29,FixedTax,2,TRUE) +((G29-VLOOKUP(G29,IncomeThreshold,1,TRUE)) * VLOOKUP(G29,TaxPercentage,3,TRUE)) -> 3355.78 | K29: =IF(AND(G29>55874,E29=TRUE), VLOOKUP(G29,HELP,2,TRUE), 0) *G29 -> 0 | L29: =(G29+H29)-(I29+J29) -> 35913.11
A30: Harrison | B30: McCallum | C30: Male | D30: Junior Child Care Worker | E30: TRUE | F30: 36257 | G30: 35862 | H30: =G30* IF(D30<>"Volunteer Carer", VLOOKUP(D30,EmployerSuper,2,FALSE),0) -> 3406.89 | I30: =IF(AND(D30<>"Volunteer Carer",YEARFRAC(DATE(2017,12,31),F30)>=25), VLOOKUP(YEARFRAC(DATE(2017,12,31),F30),EmployeeSuper,2,TRUE)*(G30-J30),0) -> 0 | J30: =VLOOKUP(G30,FixedTax,2,TRUE) +((G30-VLOOKUP(G30,IncomeThreshold,1,TRUE)) * VLOOKUP(G30,TaxPercentage,3,TRUE)) -> 3355.78 | K30: =IF(AND(G30>55874,E30=TRUE), VLOOKUP(G30,HELP,2,TRUE), 0) *G30 -> 0 | L30: =(G30+H30)-(I30+J30) -> 35913.11

Sheet Children
A1: Sunshine Children
A2: Child Code | B2: Family Code | C2: Given Name | D2: Family Name | E2: Gender | F2: DOB | G2: Days | H2: Age | I2: Initial Room | J2: Final Room | K2: Number of Days | L2: Weekday String | M2: Weekday Cost Pre Birthday | N2: Saturday Cost Pre Birthday | O2: Weekday Cost Post Birthday | P2: Saturday Cost Post Birthday | Q2: Annual Cost
K3: >=5
M6: Weekday Cost Pre Birthday | N6: Saturday Cost Pre Birthday | O6: Weekday Cost Post Birthday | P6: Saturday Cost Post Birthday | Q6: Annual Cost
L7: Total | M7: =DSUM(_xlnm.Database,M12,_xlnm.Criteria) -> 308280 | N7: =DSUM(_xlnm.Database,N12,_xlnm.Criteria) -> 79505 | O7: =DSUM(_xlnm.Database,O12,_xlnm.Criteria) -> 252760 | P7: =DSUM(_xlnm.Database,P12,_xlnm.Criteria) -> 66120 | Q7: =DSUM(_xlnm.Database,Q12,_xlnm.Criteria) -> 706665
L8: Minimum | M8: =DMIN(_xlnm.Database,M12,_xlnm.Criteria) -> 1955 | N8: =DMIN(_xlnm.Database,N12,_xlnm.Criteria) -> 0 | O8: =DMIN(_xlnm.Database,O12,_xlnm.Criteria) -> 0 | P8: =DMIN(_xlnm.Database,P12,_xlnm.Criteria) -> 0 | Q8: =DMIN(_xlnm.Database,Q12,_xlnm.Criteria) -> 18450
L9: Average | M9: =DAVERAGE(_xlnm.Database,M12,_xlnm.Criteria) -> 11010 | N9: =DAVERAGE(_xlnm.Database,N12,_xlnm.Criteria) -> 2839.4643 | O9: =DAVERAGE(_xlnm.Database,O12,_xlnm.Criteria) -> 9027.1429 | P9: =DAVERAGE(_xlnm.Database,P12,_xlnm.Criteria) -> 2361.4286 | Q9: =DAVERAGE(_xlnm.Database,Q12,_xlnm.Criteria) -> 25238.036
L10: Maximum | M10: =DMAX(_xlnm.Database,M12,_xlnm.Criteria) -> 21360 | N10: =DMAX(_xlnm.Database,N12,_xlnm.Criteria) -> 5850 | O10: =DMAX(_xlnm.Database,O12,_xlnm.Criteria) -> 23430 | P10: =DMAX(_xlnm.Database,P12,_xlnm.Criteria) -> 5290 | Q10: =DMAX(_xlnm.Database,Q12,_xlnm.Criteria) -> 38390
A12: Child Code | B12: Family Code | C12: Given Name | D12: Family Name | E12: Gender | F12: DOB | G12: Days | H12: Age | I12: Initial Room | J12: Final Room | K12: Number of Days | L12: Weekday String | M12: Weekday Cost Pre Birthday | N12: Saturday Cost Pre Birthday | O12: Weekday Cost Post Birthday | P12: Saturday Cost Post Birthday | Q12: Annual Cost
A13: allman-03-05 | B13: allman-03 | C13: Molly | D13: Allman | E13: Female | F13: 41455 | G13: mon,tues,sat | H13: =_xlfn.FLOOR.MATH(YEARFRAC(DATE(2018,1,1),F13)) -> 4 | I13: =IF(H13<6,VLOOKUP(H13,Rooms,2,TRUE),"NOT ALLOWED") -> Kangaroo Room | J13: =IF(H13+1<6,VLOOKUP(H13+1,Rooms,2,TRUE),"NOT ALLOWED") -> Kangaroo Room | K13: =IF(ISNUMBER(SEARCH("mon",G13)),1,0) + IF(ISNUMBER(SEARCH("tues",G13)),1,0) + IF(ISNUMBER(SEARCH("wed",G13)),1,0) + IF(ISNUMBER(SEARCH("thurs",G13)),1,0) + IF(ISNUMBER(SEARCH("fri",G13)),1,0) + IF(ISNUMBER(SEARCH("sat",G13)),1,0) + IF(ISNUMBER(SEARCH("sun",G13)),1,0) -> 3 | L13: =IF(ISNUMBER(SEARCH("mon",G13)),0,1) & IF(ISNUMBER(SEARCH("tues",G13)),0,1) & IF(ISNUMBER(SEARCH("wed",G13)),0,1) & IF(ISNUMBER(SEARCH("thurs",G13)),0,1) & IF(ISNUMBER(SEARCH("fri",G13)),0,1) & 1 & 1 -> 0011111 | M13: =IF(H13<6, (NETWORKDAYS.INTL(DATE(2018,1,1),DATE(2018,MONTH(F13),DAY(F13)),L13,Holidays)) * VLOOKUP(H13,CareCosts,2), 0) -> 4165 | N13: =IF(H13<6, (NETWORKDAYS.INTL(DATE(2018,1,1),DATE(2018,MONTH(F13),DAY(F13)),IF(ISNUMBER(SEARCH("sat",G13)),"1111101","1111111"),Holidays)) * (VLOOKUP(H13,CareCosts,2)+ SaturdayPenalty), 0) -> 2375 | O13: =IF(H13+1<6, (NETWORKDAYS.INTL(DATE(2018,MONTH(F13),DAY(F13)),DATE(2018,12,31),L13,Holidays)) * VLOOKUP(H13+1,CareCosts,2),0) -> 4080 | P13: =IF(H13+1<6, (NETWORKDAYS.INTL(DATE(2018,1,1),DATE(2018,MONTH(F13),DAY(F13)),IF(ISNUMBER(SEARCH("sat",G13)),"1111101","1111111"),Holidays)) * (VLOOKUP(H13+1,CareCosts,2)+ SaturdayPenalty), 0) -> 2250 | Q13: =SUM(M13,N13,O13,P13) -> 12870
A14: allman-03-04 | B14: allman-03 | C14: Regina | D14: Allman | E14: Female | F14: 41921 | G14: mon,tues,sat | H14: =_xlfn.FLOOR.MATH(YEARFRAC(DATE(2018,1,1),F14)) -> 3 | I14: =IF(H14<6,VLOOKUP(H14,Rooms,2,TRUE),"NOT ALLOWED") -> Koala Room | J14: =IF(H14+1<6,VLOOKUP(H14+1,Rooms,2,TRUE),"NOT ALLOWED") -> Kangaroo Room | K14: =IF(ISNUMBER(SEARCH("mon",G14)),1,0) + IF(ISNUMBER(SEARCH("tues",G14)),1,0) + IF(ISNUMBER(SEARCH("wed",G14)),1,0) + IF(ISNUMBER(SEARCH("thurs",G14)),1,0) + IF(ISNUMBER(SEARCH("fri",G14)),1,0) + IF(ISNUMBER(SEARCH("sat",G14)),1,0) + IF(ISNUMBER(SEARCH("sun",G14)),1,0) -> 3 | L14: =IF(ISNUMBER(SEARCH("mon",G14)),0,1) & IF(ISNUMBER(SEARCH("tues",G14)),0,1) & IF(ISNUMBER(SEARCH("wed",G14)),0,1) & IF(ISNUMBER(SEARCH("thurs",G14)),0,1) & IF(ISNUMBER(SEARCH("fri",G14)),0,1) & 1 & 1 -> 0011111 | M14: =IF(H14<6, (NETWORKDAYS.INTL(DATE(2018,1,1),DATE(2018,MONTH(F14),DAY(F14)),L14,Holidays)) * VLOOKUP(H14,CareCosts,2), 0) -> 7020 | N14: =IF(H14<6, (NETWORKDAYS.INTL(DATE(2018,1,1),DATE(2018,MONTH(F14),DAY(F14)+1),IF(ISNUMBER(SEARCH("sat",G14)),"1111101","1111111"),Holidays)) * (VLOOKUP(H14,CareCosts,2)+ SaturdayPenalty), 0) -> 3900 | O14: =IF(H14+1<6, (NETWORKDAYS.INTL(DATE(2018,MONTH(F14),DAY(F14)),DATE(2018,12,31),L14,Holidays)) * VLOOKUP(H14+1,CareCosts,2),0) -> 1955 | P14: =IF(H14+1<6, (NETWORKDAYS.INTL(DATE(2018,1,1),DATE(2018,MONTH(F14),DAY(F14)),IF(ISNUMBER(SEARCH("sat",G14)),"1111101","1111111"),Holidays)) * (VLOOKUP(H14+1,CareCosts,2)+ SaturdayPenalty), 0) -> 3705 | Q14: =SUM(M14,N14,O14,P14) -> 16580
A15: allman-03-03 | B15: allman-03 | C15: Roxanne | D15: Allman | E15: Female | F15: 42310 | G15: mon,tues,sat | H15: =_xlfn.FLOOR.MATH(YEARFRAC(DATE(2018,1,1),F15)) -> 2 | I15: =IF(H15<6,VLOOKUP(H15,Rooms,2,TRUE),"NOT ALLOWED") -> Emu Room | J15: =IF(H15+1<6,VLOOKUP(H15+1,Rooms,2,TRUE),"NOT ALLOWED") -> Koala Room | K15: =IF(ISNUMBER(SEARCH("mon",G15)),1,0) + IF(ISNUMBER(SEARCH("tues",G15)),1,0) + IF(ISNUMBER(SEARCH("wed",G15)),1,0) + IF(ISNUMBER(SEARCH("thurs",G15)),1,0) + IF(ISNUMBER(SEARCH("fri",G15)),1,0) + IF(ISNUMBER(SEARCH("sat",G15)),1,0) + IF(ISNUMBER(SEARCH("sun",G15)),1,0) -> 3 | L15: =IF(ISNUMBER(SEARCH("mon",G15)),0,1) & IF(ISNUMBER(SEARCH("tues",G15)),0,1) & IF(ISNUMBER(SEARCH("wed",G15)),0,1) & IF(ISNUMBER(SEARCH("thurs",G15)),0,1) & IF(ISNUMBER(SEARCH("fri",G15)),0,1) & 1 & 1 -> 0011111 | M15: =IF(H15<6, (NETWORKDAYS.INTL(DATE(2018,1,1),DATE(2018,MONTH(F15),DAY(F15)),L15,Holidays)) * VLOOKUP(H15,CareCosts,2), 0) -> 8820 | N15: =IF(H15<6, (NETWORKDAYS.INTL(DATE(2018,1,1),DATE(2018,MONTH(F15),DAY(F15)+1),IF(ISNUMBER(SEARCH("sat",G15)),"1111101","1111111"),Holidays)) * (VLOOKUP(H15,CareCosts,2)+ SaturdayPenalty), 0) -> 4945 | O15: =IF(H15+1<6, (NETWORKDAYS.INTL(DATE(2018,MONTH(F15),DAY(F15)),DATE(2018,12,31),L15,Holidays)) * VLOOKUP(H15+1,CareCosts,2),0) -> 1440 | P15: =IF(H15+1<6, (NETWORKDAYS.INTL(DATE(2018,1,1),DATE(2018,MONTH(F15),DAY(F15)),IF(ISNUMBER(SEARCH("sat",G15)),"1111101","1111111"),Holidays)) * (VLOOKUP(H15+1,CareCosts,2)+ SaturdayPenalty), 0) -> 4200 | Q15: =SUM(M15,N15,O15,P15) -> 19405
A16: allman-03-02 | B16: allman-03 | C16: Jeffery | D16: Allman | E16: Male | F16: 43095 | G16: mon,tues,sat | H16: =_xlfn.FLOOR.MATH(YEARFRAC(DATE(2018,1,1),F16)) -> 0 | I16: =IF(H16<6,VLOOKUP(H16,Rooms,2,TRUE),"NOT ALLOWED") -> Platypus Room | J16: =IF(H16+1<6,VLOOKUP(H16+1,Rooms,2,TRUE),"NOT ALLOWED") -> Platypus Room | K16: =IF(ISNUMBER(SEARCH("mon",G16)),1,0) + IF(ISNUMBER(SEARCH("tues",G16)),1,0) + IF(ISNUMBER(SEARCH("wed",G16)),1,0) + IF(ISNUMBER(SEARCH("thurs",G16)),1,0) + IF(ISNUMBER(SEARCH("fri",G16)),1,0) + IF(ISNUMBER(SEARCH("sat",G16)),1,0) + IF(ISNUMBER(SEARCH("sun",G16)),1,0) -> 3 | L16: =IF(ISNUMBER(SEARCH("mon",G16)),0,1) & IF(ISNUMBER(SEARCH("tues",G16)),0,1) & IF(ISNUMBER(SEARCH("wed",G16)),0,1) & IF(ISNUMBER(SEARCH("thurs",G16)),0,1) & IF(ISNUMBER(SEARCH("fri",G16)),0,1) & 1 & 1 -> 0011111 | M16: =IF(H16<6, (NETWORKDAYS.INTL(DATE(2018,1,1),DATE(2018,MONTH(F16),DAY(F16)),L16,Holidays)) * VLOOKUP(H16,CareCosts,2), 0) -> 11880 | N16: =IF(H16<6, (NETWORKDAYS.INTL(DATE(2018,1,1),DATE(2018,MONTH(F16),DAY(F16)+1),IF(ISNUMBER(SEARCH("sat",G16)),"1111101","1111111"),Holidays)) * (VLOOKUP(H16,CareCosts,2)+ SaturdayPenalty), 0) -> 6500 | O16: =IF(H16+1<6, (NETWORKDAYS.INTL(DATE(2018,MONTH(F16),DAY(F16)),DATE(2018,12,31),L16,Holidays)) * VLOOKUP(H16+1,CareCosts,2),0) -> 110 | P16: =IF(H16+1<6, (NETWORKDAYS.INTL(DATE(2018,1,1),DATE(2018,MONTH(F16),DAY(F16)),IF(ISNUMBER(SEARCH("sat",G16)),"1111101","1111111"),Holidays)) * (VLOOKUP(H16+1,CareCosts,2)+ SaturdayPenalty), 0) -> 6000 | Q16: =SUM(M16,N16,O16,P16) -> 24490
A17: barclay-02-02 | B17: barclay-02 | C17: Jennifer | D17: Barclay | E17: Female | F17: 42785 | G17: tues,wed | H17: =_xlfn.FLOOR.MATH(YEARFRAC(DATE(2018,1,1),F17)) -> 0 | I17: =IF(H17<6,VLOOKUP(H17,Rooms,2,TRUE),"NOT ALLOWED") -> Platypus Room | J17: =IF(H17+1<6,VLOOKUP(H17+1,Rooms,2,TRUE),"NOT ALLOWED") -> Platypus Room | K17: =IF(ISNUMBER(SEARCH("mon",G17)),1,0) + IF(ISNUMBER(SEARCH("tues",G17)),1,0) + IF(ISNUMBER(SEARCH("wed",G17)),1,0) + IF(ISNUMBER(SEARCH("thurs",G17)),1,0) + IF(ISNUMBER(SEARCH("fri",G17)),1,0) + IF(ISNUMBER(SEARCH("sat",G17)),1,0) + IF(ISNUMBER(SEARCH("sun",G17)),1,0) -> 2 | L17: =IF(ISNUMBER(SEARCH("mon",G17)),0,1) & IF(ISNUMBER(SEARCH("tues",G17)),0,1) & IF(ISNUMBER(SEARCH("wed",G17)),0,1) & IF(ISNUMBER(SEARCH("thurs",G17)),0,1) & IF(ISNUMBER(SEARCH("fri",G17)),0,1) & 1 & 1 -> 1001111 | M17: =IF(H17<6, (NETWORKDAYS.INTL(DATE(2018,1,1),DATE(2018,MONTH(F17),DAY(F17)),L17,Holidays)) * VLOOKUP(H17,CareCosts,2), 0) -> 1680 | N17: =IF(H17<6, (NETWORKDAYS.INTL(DATE(2018,1,1),DATE(2018,MONTH(F17),DAY(F17)+1),IF(ISNUMBER(SEARCH("sat",G17)),"1111101","1111111"),Holidays)) * (VLOOKUP(H17,CareCosts,2)+ SaturdayPenalty), 0) -> 0 | O17: =IF(H17+1<6, (NETWORKDAYS.INTL(DATE(2018,MONTH(F17),DAY(F17)),DATE(2018,12,31),L17,Holidays)) * VLOOKUP(H17+1,CareCosts,2),0) -> 9460 | P17: =IF(H17+1<6, (NETWORKDAYS.INTL(DATE(2018,1,1),DATE(2018,MONTH(F17),DAY(F17)),IF(ISNUMBER(SEARCH("sat",G17)),"1111101","1111111"),Holidays)) * (VLOOKUP(H17+1,CareCosts,2)+ SaturdayPenalty), 0) -> 0 | Q17: =SUM(M17,N17,O17,P17) -> 11140
A18: barclay-02-01 | B18: barclay-02 | C18: Robert | D18: Barclay | E18: Male | F18: 42785 | G18: tues,wed | H18: =_xlfn.FLOOR.MATH(YEARFRAC(DATE(2018,1,1),F18)) -> 0 | I18: =IF(H18<6,VLOOKUP(H18,Rooms,2,TRUE),"NOT ALLOWED") -> Platypus Room | J18: =IF(H18+1<6,VLOOKUP(H18+1,Rooms,2,TRUE),"NOT ALLOWED") -> Platypus Room | K18: =IF(ISNUMBER(SEARCH("mon",G18)),1,0) + IF(ISNUMBER(SEARCH("tues",G18)),1,0) + IF(ISNUMBER(SEARCH("wed",G18)),1,0) + IF(ISNUMBER(SEARCH("thurs",G18)),1,0) + IF(ISNUMBER(SEARCH("fri",G18)),1,0) + IF(ISNUMBER(SEARCH("sat",G18)),1,0) + IF(ISNUMBER(SEARCH("sun",G18)),1,0) -> 2 | L18: =IF(ISNUMBER(SEARCH("mon",G18)),0,1) & IF(ISNUMBER(SEARCH("tues",G18)),0,1) & IF(ISNUMBER(SEARCH("wed",G18)),0,1) & IF(ISNUMBER(SEARCH("thurs",G18)),0,1) & IF(ISNUMBER(SEARCH("fri",G18)),0,1) & 1 & 1 -> 1001111 | M18: =IF(H18<6, (NETWORKDAYS.INTL(DATE(2018,1,1),DATE(2018,MONTH(F18),DAY(F18)),L18,Holidays)) * VLOOKUP(H18,CareCosts,2), 0) -> 1680 | N18: =IF(H18<6, (NETWORKDAYS.INTL(DATE(2018,1,1),DATE(2018,MONTH(F18),DAY(F18)+1),IF(ISNUMBER(SEARCH("sat",G18)),"1111101","1111111"),Holidays)) * (VLOOKUP(H18,CareCosts,2)+ SaturdayPenalty), 0) -> 0 | O18: =IF(H18+1<6, (NETWORKDAYS.INTL(DATE(2018,MONTH(F18),DAY(F18)),DATE(2018,12,31),L18,Holidays)) * VLOOKUP(H18+1,CareCosts,2),0) -> 9460 | P18: =IF(H18+1<6, (NETWORKDAYS.INTL(DATE(2018,1,1),DATE(2018,MONTH(F18),DAY(F18)),IF(ISNUMBER(SEARCH("sat",G18)),"1111101","1111111"),Holidays)) * (VLOOKUP(H18+1,CareCosts,2)+ SaturdayPenalty), 0) -> 0 | Q18: =SUM(M18,N18,O18,P18) -> 11140
A19: barnard-02-03 | B19: barnard-02 | C19: Brandon | D19: Barnard | E19: Male | F19: 41980 | G19: fri,sat | H19: =_xlfn.FLOOR.MATH(YEARFRAC(DATE(2018,1,1),F19)) -> 3 | I19: =IF(H19<6,VLOOKUP(H19,Rooms,2,TRUE),"NOT ALLOWED") -> Koala Room | J19: =IF(H19+1<6,VLOOKUP(H19+1,Rooms,2,TRUE),"NOT ALLOWED") -> Kangaroo Room | K19: =IF(ISNUMBER(SEARCH("mon",G19)),1,0) + IF(ISNUMBER(SEARCH("tues",G19)),1,0) + IF(ISNUMBER(SEARCH("wed",G19)),1,0) + IF(ISNUMBER(SEARCH("thurs",G19)),1,0) + IF(ISNUMBER(SEARCH("fri",G19)),1,0) + IF(ISNUMBER(SEARCH("sat",G19)),1,0) + IF(ISNUMBER(SEARCH("sun",G19)),1,0) -> 2 | L19: =IF(ISNUMBER(SEARCH("mon",G19)),0,1) & IF(ISNUMBER(SEARCH("tues",G19)),0,1) & IF(ISNUMBER(SEARCH("wed",G19)),0,1) & IF(ISNUMBER(SEARCH("thurs",G19)),0,1) & IF(ISNUMBER(SEARCH("fri",G19)),0,1) & 1 & 1 -> 1111011 | M19: =IF(H19<6, (NETWORKDAYS.INTL(DATE(2018,1,1),DATE(2018,MONTH(F19),DAY(F19)),L19,Holidays)) * VLOOKUP(H19,CareCosts,2), 0) -> 4230 | N19: =IF(H19<6, (NETWORKDAYS.INTL(DATE(2018,1,1),DATE(2018,MONTH(F19),DAY(F19)+1),IF(ISNUMBER(SEARCH("sat",G19)),"1111101","1111111"),Holidays)) * (VLOOKUP(H19,CareCosts,2)+ SaturdayPenalty), 0) -> 4800 | O19: =IF(H19+1<6, (NETWORKDAYS.INTL(DATE(2018,MONTH(F19),DAY(F19)),DATE(2018,12,31),L19,Holidays)) * VLOOKUP(H19+1,CareCosts,2),0) -> 340 | P19: =IF(H19+1<6, (NETWORKDAYS.INTL(DATE(2018,1,1),DATE(2018,MONTH(F19),DAY(F19)),IF(ISNUMBER(SEARCH("sat",G19)),"1111101","1111111"),Holidays)) * (VLOOKUP(H19+1,CareCosts,2)+ SaturdayPenalty), 0) -> 4465 | Q19: =SUM(M19,N19,O19,P19) -> 13835
A20: barnard-02-04 | B20: barnard-02 | C20: Janis | D20: Barnard | E20: Female | F20: 41980 | G20: fri,sat | H20: =_xlfn.FLOOR.MATH(YEARFRAC(DATE(2018,1,1),F20)) -> 3 | I20: =IF(H20<6,VLOOKUP(H20,Rooms,2,TRUE),"NOT ALLOWED") -> Koala Room | J20: =IF(H20+1<6,VLOOKUP(H20+1,Rooms,2,TRUE),"NOT ALLOWED") -> Kangaroo Room | K20: =IF(ISNUMBER(SEARCH("mon",G20)),1,0) + IF(ISNUMBER(SEARCH("tues",G20)),1,0) + IF(ISNUMBER(SEARCH("wed",G20)),1,0) + IF(ISNUMBER(SEARCH("thurs",G20)),1,0) + IF(ISNUMBER(SEARCH("fri",G20)),1,0) + IF(ISNUMBER(SEARCH("sat",G20)),1,0) + IF(ISNUMBER(SEARCH("sun",G20)),1,0) -> 2 | L20: =IF(ISNUMBER(SEARCH("mon",G20)),0,1) & IF(ISNUMBER(SEARCH("tues",G20)),0,1) & IF(ISNUMBER(SEARCH("wed",G20)),0,1) & IF(ISNUMBER(SEARCH("thurs",G20)),0,1) & IF(ISNUMBER(SEARCH("fri",G20)),0,1) & 1 & 1 -> 1111011 | M20: =IF(H20<6, (NETWORKDAYS.INTL(DATE(2018,1,1),DATE(2018,MONTH(F20),DAY(F20)),L20,Holidays)) * VLOOKUP(H20,CareCosts,2), 0) -> 4230 | N20: =IF(H20<6, (NETWORKDAYS.INTL(DATE(2018,1,1),DATE(2018,MONTH(F20),DAY(F20)+1),IF(ISNUMBER(SEARCH("sat",G20)),"1111101","1111111"),Holidays)) * (VLOOKUP(H20,CareCosts,2)+ SaturdayPenalty), 0) -> 4800 | O20: =IF(H20+1<6, (NETWORKDAYS.INTL(DATE(2018,MONTH(F20),DAY(F20)),DATE(2018,12,31),L20,Holidays)) * VLOOKUP(H20+1,CareCosts,2),0) -> 340 | P20: =IF(H20+1<6, (NETWORKDAYS.INTL(DATE(2018,1,1),DATE(2018,MONTH(F20),DAY(F20)),IF(ISNUMBER(SEARCH("sat",G20)),"1111101","1111111"),Holidays)) * (VLOOKUP(H20+1,CareCosts,2)+ SaturdayPenalty), 0) -> 4465 | Q20: =SUM(M20,N20,O20,P20) -> 13835
A21: barnard-02-02 | B21: barnard-02 | C21: Madeline | D21: Barnard | E21: Female | F21: 41980 | G21: fri,sat | H21: =_xlfn.FLOOR.MATH(YEARFRAC(DATE(2018,1,1),F21)) -> 3 | I21: =IF(H21<6,VLOOKUP(H21,Rooms,2,TRUE),"NOT ALLOWED") -> Koala Room | J21: =IF(H21+1<6,VLOOKUP(H21+1,Rooms,2,TRUE),"NOT ALLOWED") -> Kangaroo Room | K21: =IF(ISNUMBER(SEARCH("mon",G21)),1,0) + IF(ISNUMBER(SEARCH("tues",G21)),1,0) + IF(ISNUMBER(SEARCH("wed",G21)),1,0) + IF(ISNUMBER(SEARCH("thurs",G21)),1,0) + IF(ISNUMBER(SEARCH("fri",G21)),1,0) + IF(ISNUMBER(SEARCH("sat",G21)),1,0) + IF(ISNUMBER(SEARCH("sun",G21)),1,0) -> 2 | L21: =IF(ISNUMBER(SEARCH("mon",G21)),0,1) & IF(ISNUMBER(SEARCH("tues",G21)),0,1) & IF(ISNUMBER(SEARCH("wed",G21)),0,1) & IF(ISNUMBER(SEARCH("thurs",G21)),0,1) & IF(ISNUMBER(SEARCH("fri",G21)),0,1) & 1 & 1 -> 1111011 | M21: =IF(H21<6, (NETWORKDAYS.INTL(DATE(2018,1,1),DATE(2018,MONTH(F21),DAY(F21)),L21,Holidays)) * VLOOKUP(H21,CareCosts,2), 0) -> 4230 | N21: =IF(H21<6, (NETWORKDAYS.INTL(DATE(2018,1,1),DATE(2018,MONTH(F21),DAY(F21)+1),IF(ISNUMBER(SEARCH("sat",G21)),"1111101","1111111"),Holidays)) * (VLOOKUP(H21,CareCosts,2)+ SaturdayPenalty), 0) -> 4800 | O21: =IF(H21+1<6, (NETWORKDAYS.INTL(DATE(2018,MONTH(F21),DAY(F21)),DATE(2018,12,31),L21,Holidays)) * VLOOKUP(H21+1,CareCosts,2),0) -> 340 | P21: =IF(H21+1<6, (NETWORKDAYS.INTL(DATE(2018,1,1),DATE(2018,MONTH(F21),DAY(F21)),IF(ISNUMBER(SEARCH("sat",G21)),"1111101","1111111"),Holidays)) * (VLOOKUP(H21+1,CareCosts,2)+ SaturdayPenalty), 0) -> 4465 | Q21: =SUM(M21,N21,O21,P21) -> 13835
A22: barnard-02-05 | B22: barnard-02 | C22: Robert | D22: Barnard | E22: Male | F22: 41980 | G22: fri,sat | H22: =_xlfn.FLOOR.MATH(YEARFRAC(DATE(2018,1,1),F22)) -> 3 | I22: =IF(H22<6,VLOOKUP(H22,Rooms,2,TRUE),"NOT ALLOWED") -> Koala Room | J22: =IF(H22+1<6,VLOOKUP(H22+1,Rooms,2,TRUE),"NOT ALLOWED") -> Kangaroo Room | K22: =IF(ISNUMBER(SEARCH("mon",G22)),1,0) + IF(ISNUMBER(SEARCH("tues",G22)),1,0) + IF(ISNUMBER(SEARCH("wed",G22)),1,0) + IF(ISNUMBER(SEARCH("thurs",G22)),1,0) + IF(ISNUMBER(SEARCH("fri",G22)),1,0) + IF(ISNUMBER(SEARCH("sat",G22)),1,0) + IF(ISNUMBER(SEARCH("sun",G22)),1,0) -> 2 | L22: =IF(ISNUMBER(SEARCH("mon",G22)),0,1) & IF(ISNUMBER(SEARCH("tues",G22)),0,1) & IF(ISNUMBER(SEARCH("wed",G22)),0,1) & IF(ISNUMBER(SEARCH("thurs",G22)),0,1) & IF(ISNUMBER(SEARCH("fri",G22)),0,1) & 1 & 1 -> 1111011 | M22: =IF(H22<6, (NETWORKDAYS.INTL(DATE(2018,1,1),DATE(2018,MONTH(F22),DAY(F22)),L22,Holidays)) * VLOOKUP(H22,CareCosts,2), 0) -> 4230 | N22: =IF(H22<6, (NETWORKDAYS.INTL(DATE(2018,1,1),DATE(2018,MONTH(F22),DAY(F22)+1),IF(ISNUMBER(SEARCH("sat",G22)),"1111101","1111111"),Holidays)) * (VLOOKUP(H22,CareCosts,2)+ SaturdayPenalty), 0) -> 4800 | O22: =IF(H22+1<6, (NETWORKDAYS.INTL(DATE(2018,MONTH(F22),DAY(F22)),DATE(2018,12,31),L22,Holidays)) * VLOOKUP(H22+1,CareCosts,2),0) -> 340 | P22: =IF(H22+1<6, (NETWORKDAYS.INTL(DATE(2018,1,1),DATE(2018,MONTH(F22),DAY(F22)),IF(ISNUMBER(SEARCH("sat",G22)),"1111101","1111111"),Holidays)) * (VLOOKUP(H22+1,CareCosts,2)+ SaturdayPenalty), 0) -> 4465 | Q22: =SUM(M22,N22,O22,P22) -> 13835
A23: bernardini-02-01 | B23: bernardini-02 | C23: Heath | D23: Bernardini | E23: Male | F23: 42703 | G23: tues,wed,thurs,fri,sat | H23: =_xlfn.FLOOR.MATH(YEARFRAC(DATE(2018,1,1),F23)) -> 1 | I23: =IF(H23<6,VLOOKUP(H23,Rooms,2,TRUE),"NOT ALLOWED") -> Platypus Room | J23: =IF(H23+1<6,VLOOKUP(H23+1,Rooms,2,TRUE),"NOT ALLOWED") -> Emu Room | K23: =IF(ISNUMBER(SEARCH("mon",G23)),1,0) + IF(ISNUMBER(SEARCH("tues",G23)),1,0) + IF(ISNUMBER(SEARCH("wed",G23)),1,0) + IF(ISNUMBER(SEARCH("thurs",G23)),1,0) + IF(ISNUMBER(SEARCH("fri",G23)),1,0) + IF(ISNUMBER(SEARCH("sat",G23)),1,0) + IF(ISNUMBER(SEARCH("sun",G23)),1,0) -> 5 | L23: =IF(ISNUMBER(SEARCH("mon",G23)),0,1) & IF(ISNUMBER(SEARCH("tues",G23)),0,1) & IF(ISNUMBER(SEARCH("wed",G23)),0,1) & IF(ISNUMBER(SEARCH("thurs",G23)),0,1) & IF(ISNUMBER(SEARCH("fri",G23)),0,1) & 1 & 1 -> 1000011 | M23: =IF(H23<6, (NETWORKDAYS.INTL(DATE(2018,1,1),DATE(2018,MONTH(F23),DAY(F23)),L23,Holidays)) * VLOOKUP(H23,CareCosts,2), 0) -> 20570 | N23: =IF(H23<6, (NETWORKDAYS.INTL(DATE(2018,1,1),DATE(2018,MONTH(F23),DAY(F23)+1),IF(ISNUMBER(SEARCH("sat",G23)),"1111101","1111111"),Holidays)) * (VLOOKUP(H23,CareCosts,2)+ SaturdayPenalty), 0) -> 5520 | O23: =IF(H23+1<6, (NETWORKDAYS.INTL(DATE(2018,MONTH(F23),DAY(F23)),DATE(2018,12,31),L23,Holidays)) * VLOOKUP(H23+1,CareCosts,2),0) -> 1680 | P23: =IF(H23+1<6, (NETWORKDAYS.INTL(DATE(2018,1,1),DATE(2018,MONTH(F23),DAY(F23)),IF(ISNUMBER(SEARCH("sat",G23)),"1111101","1111111"),Holidays)) * (VLOOKUP(H23+1,CareCosts,2)+ SaturdayPenalty), 0) -> 5290 | Q23: =SUM(M23,N23,O23,P23) -> 33060
A24: bruner-03-01 | B24: bruner-03 | C24: Jonas | D24: Bruner | E24: Male | F24: 41772 | G24: mon,tues,wed,sat | H24: =_xlfn.FLOOR.MATH(YEARFRAC(DATE(2018,1,1),F24)) -> 3 | I24: =IF(H24<6,VLOOKUP(H24,Rooms,2,TRUE),"NOT ALLOWED") -> Koala Room | J24: =IF(H24+1<6,VLOOKUP(H24+1,Rooms,2,TRUE),"NOT ALLOWED") -> Kangaroo Room | K24: =IF(ISNUMBER(SEARCH("mon",G24)),1,0) + IF(ISNUMBER(SEARCH("tues",G24)),1,0) + IF(ISNUMBER(SEARCH("wed",G24)),1,0) + IF(ISNUMBER(SEARCH("thurs",G24)),1,0) + IF(ISNUMBER(SEARCH("fri",G24)),1,0) + IF(ISNUMBER(SEARCH("sat",G24)),1,0) + IF(ISNUMBER(SEARCH("sun",G24)),1,0) -> 4 | L24: =IF(ISNUMBER(SEARCH("mon",G24)),0,1) & IF(ISNUMBER(SEARCH("tues",G24)),0,1) & IF(ISNUMBER(SEARCH("wed",G24)),0,1) & IF(ISNUMBER(SEARCH("thurs",G24)),0,1) & IF(ISNUMBER(SEARCH("fri",G24)),0,1) & 1 & 1 -> 0001111 | M24: =IF(H24<6, (NETWORKDAYS.INTL(DATE(2018,1,1),DATE(2018,MONTH(F24),DAY(F24)),L24,Holidays)) * VLOOKUP(H24,CareCosts,2), 0) -> 4770 | N24: =IF(H24<6, (NETWORKDAYS.INTL(DATE(2018,1,1),DATE(2018,MONTH(F24),DAY(F24)+1),IF(ISNUMBER(SEARCH("sat",G24)),"1111101","1111111"),Holidays)) * (VLOOKUP(H24,CareCosts,2)+ SaturdayPenalty), 0) -> 1800 | O24: =IF(H24+1<6, (NETWORKDAYS.INTL(DATE(2018,MONTH(F24),DAY(F24)),DATE(2018,12,31),L24,Holidays)) * VLOOKUP(H24+1,CareCosts,2),0) -> 8160 | P24: =IF(H24+1<6, (NETWORKDAYS.INTL(DATE(2018,1,1),DATE(2018,MONTH(F24),DAY(F24)),IF(ISNUMBER(SEARCH("sat",G24)),"1111101","1111111"),Holidays)) * (VLOOKUP(H24+1,CareCosts,2)+ SaturdayPenalty), 0) -> 1710 | Q24: =SUM(M24,N24,O24,P24) -> 16440
A25: burke-02-02 | B25: burke-02 | C25: Micael | D25: Burke | E25: Male | F25: 42061 | G25: tues,thurs,fri,sat | H25: =_xlfn.FLOOR.MATH(YEARFRAC(DATE(2018,1,1),F25)) -> 2 | I25: =IF(H25<6,VLOOKUP(H25,Rooms,2,TRUE),"NOT ALLOWED") -> Emu Room | J25: =IF(H25+1<6,VLOOKUP(H25+1,Rooms,2,TRUE),"NOT ALLOWED") -> Koala Room | K25: =IF(ISNUMBER(SEARCH("mon",G25)),1,0) + IF(ISNUMBER(SEARCH("tues",G25)),1,0) + IF(ISNUMBER(SEARCH("wed",G25)),1,0) + IF(ISNUMBER(SEARCH("thurs",G25)),1,0) + IF(ISNUMBER(SEARCH("fri",G25)),1,0) + IF(ISNUMBER(SEARCH("sat",G25)),1,0) + IF(ISNUMBER(SEARCH("sun",G25)),1,0) -> 4 | L25: =IF(ISNUMBER(SEARCH("mon",G25)),0,1) & IF(ISNUMBER(SEARCH("tues",G25)),0,1) & IF(ISNUMBER(SEARCH("wed",G25)),0,1) & IF(ISNUMBER(SEARCH("thurs",G25)),0,1) & IF(ISNUMBER(SEARCH("fri",G25)),0,1) & 1 & 1 -> 1010011 | M25: =IF(H25<6, (NETWORKDAYS.INTL(DATE(2018,1,1),DATE(2018,MONTH(F25),DAY(F25)),L25,Holidays)) * VLOOKUP(H25,CareCosts,2), 0) -> 2415 | N25: =IF(H25<6, (NETWORKDAYS.INTL(DATE(2018,1,1),DATE(2018,MONTH(F25),DAY(F25)+1),IF(ISNUMBER(SEARCH("sat",G25)),"1111101","1111111"),Holidays)) * (VLOOKUP(H25,CareCosts,2)+ SaturdayPenalty), 0) -> 920 | O25: =IF(H25+1<6, (NETWORKDAYS.INTL(DATE(2018,MONTH(F25),DAY(F25)),DATE(2018,12,31),L25,Holidays)) * VLOOKUP(H25+1,CareCosts,2),0) -> 11700 | P25: =IF(H25+1<6, (NETWORKDAYS.INTL(DATE(2018,1,1),DATE(2018,MONTH(F25),DAY(F25)),IF(ISNUMBER(SEARCH("sat",G25)),"1111101","1111111"),Holidays)) * (VLOOKUP(H25+1,CareCosts,2)+ SaturdayPenalty), 0) -> 800 | Q25: =SUM(M25,N25,O25,P25) -> 15835
... A128: yost-02-05 | B128: yost-02 | C128: Angelica | D128: Yost | E128: Female | F128: 43055 | G128: mon,tues,thurs,fri,sat | H128: =_xlfn.FLOOR.MATH(YEARFRAC(DATE(2018,1,1),F128)) -> 0 | I128: =IF(H128<6,VLOOKUP(H128,Rooms,2,TRUE),"NOT ALLOWED") -> Platypus Room | J128: =IF(H128+1<6,VLOOKUP(H128+1,Rooms,2,TRUE),"NOT ALLOWED") -> Platypus Room | K128: =IF(ISNUMBER(SEARCH("mon",G128)),1,0) + IF(ISNUMBER(SEARCH("tues",G128)),1,0) + IF(ISNUMBER(SEARCH("wed",G128)),1,0) + IF(ISNUMBER(SEARCH("thurs",G128)),1,0) + IF(ISNUMBER(SEARCH("fri",G128)),1,0) + IF(ISNUMBER(SEARCH("sat",G128)),1,0) + IF(ISNUMBER(SEARCH("sun",G128)),1,0) -> 5 | L128: =IF(ISNUMBER(SEARCH("mon",G128)),0,1) & IF(ISNUMBER(SEARCH("tues",G128)),0,1) & IF(ISNUMBER(SEARCH("wed",G128)),0,1) & IF(ISNUMBER(SEARCH("thurs",G128)),0,1) & IF(ISNUMBER(SEARCH("fri",G128)),0,1) & 1 & 1 -> 0010011 | M128: =IF(H128<6, (NETWORKDAYS.INTL(DATE(2018,1,1),DATE(2018,MONTH(F128),DAY(F128)),L128,Holidays)) * VLOOKUP(H128,CareCosts,2), 0) -> 21360 | N128: =IF(H128<6, (NETWORKDAYS.INTL(DATE(2018,1,1),DATE(2018,MONTH(F128),DAY(F128)+1),IF(ISNUMBER(SEARCH("sat",G128)),"1111101","1111111"),Holidays)) * (VLOOKUP(H128,CareCosts,2)+ SaturdayPenalty), 0) -> 5850 | O128: =IF(H128+1<6, (NETWORKDAYS.INTL(DATE(2018,MONTH(F128),DAY(F128)),DATE(2018,12,31),L128,Holidays)) * VLOOKUP(H128+1,CareCosts,2),0) -> 2750 | P128: =IF(H128+1<6, (NETWORKDAYS.INTL(DATE(2018,1,1),DATE(2018,MONTH(F128),DAY(F128)),IF(ISNUMBER(SEARCH("sat",G128)),"1111101","1111111"),Holidays)) * (VLOOKUP(H128+1,CareCosts,2)+ SaturdayPenalty), 0) -> 5280 | Q128: =SUM(M128,N128,O128,P128) -> 35240

Sheet ChildrenPivotTable
A3: Initial Number of Male and Female in Sunshine Childcare Rooms
A4: Initial Room | B4: Female | C4: Male | D4: Grand Total
A5: Emu Room | B5: 15 | C5: 16 | D5: 31
A6: 2 | B6: 15 | C6: 16 | D6: 31
A7: Kangaroo Room | B7: 11 | C7: 17 | D7: 28
A8: 4 | B8: 10 | C8: 15 | D8: 25
A9: 5 | B9: 1 | C9: 2 | D9: 3
A10: Koala Room | B10: 13 | C10: 19 | D10: 32
A11: 3 | B11: 13 | C11: 19 | D11: 32
A12: Platypus Room | B12: 12 | C12: 13 | D12: 25
A13: 0 | B13: 6 | C13: 7 | D13: 13
A14: 1 | B14: 6 | C14: 6 | D14: 12
A15: Grand Total | B15: 51 | C15: 65 | D15: 116

Sheet Families
A1: Sunshine Families
A2: Family Code | B2: Family Name | C2: Parent/Guardian 1 Given Name | D2: Parent/Guardian 1 Family Name | E2: Parent/Guardian 2 Given Name | F2: Parent/Guardian 2 Family Name | G2: Family Income | H2: Number of Children | I2: Weekly Hours | J2: Annual Cost | K2: Annual CCB | L2: Annual CCR | M2: Annual Payable
A3: allman-03 | B3: Allman | C3: Jessica | D3: Allman | E3: Grant | F3: Allman | G3: 116538 | H3: =COUNTIF(Children!$B$13:$B$128,A3) -> 4 | I3: =10*SUMIFS(Children!$K$13:$K$128,Children!$B$13:$B$128,Families!A3) -> 120 | J3: =SUMIFS(Children!$Q$13:$Q$128,Children!$B$13:$B$128,Families!A3) -> 73345 | K3: =MAX(0,IF(G3<CCBThreshold, IF(I3/H3<CCBMaxHours, I3*52*CCBHourlyRate, 50*52*CCBHourlyRate ), IF(I3/H3<CCBMaxHours, I3*52*(CCBHourlyRate-(G3-CCBThreshold)*CCBThresholdModifier), 50*52*(CCBHourlyRate-(G3-CCBThreshold)*CCBThresholdModifier) ) )) -> 1589.6026 | L3: =MIN((J3-K3) * CCRRate, (CCRMax*H3)) -> 30452 | M3: =J3-(K3+L3) -> 41303.397
A4: barclay-02 | B4: Barclay | C4: Lucas | D4: Barclay | E4: Rosalie | F4: Barclay | G4: 117463 | H4: =COUNTIF(Children!$B$13:$B$128,A4) -> 2 | I4: =10*SUMIFS(Children!$K$13:$K$128,Children!$B$13:$B$128,Families!A4) -> 40 | J4: =SUMIFS(Children!$Q$13:$Q$128,Children!$B$13:$B$128,Families!A4) -> 22280 | K4: =MAX(0,IF(G4<CCBThreshold, IF(I4/H4<CCBMaxHours, I4*52*CCBHourlyRate, 50*52*CCBHourlyRate ), IF(I4/H4<50, I4*52*(CCBHourlyRate-(G4-CCBThreshold)*CCBThresholdModifier), 50*52*(CCBHourlyRate-(G4-CCBThreshold)*CCBThresholdModifier) ) )) -> 517.36152 | L4: =MIN((J4-K4) * CCRRate, (CCRMax*H4)) -> 10881.319 | M4: =J4-(K4+L4) -> 10881.319
A5: barnard-02 | B5: Barnard | C5: Mitchell | D5: Barnard | E5: Bethany | F5: Abrahamsson | G5: 191401 | H5: =COUNTIF(Children!$B$13:$B$128,A5) -> 4 | I5: =10*SUMIFS(Children!$K$13:$K$128,Children!$B$13:$B$128,Families!A5) -> 80 | J5: =SUMIFS(Children!$Q$13:$Q$128,Children!$B$13:$B$128,Families!A5) -> 55340 | K5: =MAX(0,IF(G5<CCBThreshold, IF(I5/H5<CCBMaxHours, I5*52*CCBHourlyRate, 50*52*CCBHourlyRate ), IF(I5/H5<50, I5*52*(CCBHourlyRate-(G5-CCBThreshold)*CCBThresholdModifier), 50*52*(CCBHourlyRate-(G5-CCBThreshold)*CCBThresholdModifier) ) )) -> 0 | L5: =MIN((J5-K5) * CCRRate, (CCRMax*H5)) -> 27670 | M5: =J5-(K5+L5) -> 27670
A6: bernardini-02 | B6: Bernardini | C6: Hiram | D6: Bernardini | E6: Heather | F6: Bernardini | G6: 72685 | H6: =COUNTIF(Children!$B$13:$B$128,A6) -> 1 | I6: =10*SUMIFS(Children!$K$13:$K$128,Children!$B$13:$B$128,Families!A6) -> 50 | J6: =SUMIFS(Children!$Q$13:$Q$128,Children!$B$13:$B$128,Families!A6) -> 33060 | K6: =MAX(0,IF(G6<CCBThreshold, IF(I6/H6<CCBMaxHours, I6*52*CCBHourlyRate, 50*52*CCBHourlyRate ), IF(I6/H6<50, I6*52*(CCBHourlyRate-(G6-CCBThreshold)*CCBThresholdModifier), 50*52*(CCBHourlyRate-(G6-CCBThreshold)*CCBThresholdModifier) ) )) -> 1403.4501 | L6: =MIN((J6-K6) * CCRRate, (CCRMax*H6)) -> 7613 | M6: =J6-(K6+L6) -> 24043.55
A7: bruner-03 | B7: Bruner | C7: Clarence | D7: Bruner | E7: Jill | F7: Bruner | G7: 85772 | H7: =COUNTIF(Children!$B$13:$B$128,A7) -> 1 | I7: =10*SUMIFS(Children!$K$13:$K$128,Children!$B$13:$B$128,Families!A7) -> 40 | J7: =SUMIFS(Children!$Q$13:$Q$128,Children!$B$13:$B$128,Families!A7) -> 16440 | K7: =MAX(0,IF(G7<CCBThreshold, IF(I7/H7<CCBMaxHours, I7*52*CCBHourlyRate, 50*52*CCBHourlyRate ), IF(I7/H7<50, I7*52*(CCBHourlyRate-(G7-CCBThreshold)*CCBThresholdModifier), 50*52*(CCBHourlyRate-(G7-CCBThreshold)*CCBThresholdModifier) ) )) -> 945.82384 | L7: =MIN((J7-K7) * CCRRate, (CCRMax*H7)) -> 7613 | M7: =J7-(K7+L7) -> 7881.1762
A8: burke-02 | B8: Burke | C8: Don | D8: Burke | E8: Norma | F8: Burke | G8: 168529 | H8: =COUNTIF(Children!$B$13:$B$128,A8) -> 1 | I8: =10*SUMIFS(Children!$K$13:$K$128,Children!$B$13:$B$128,Families!A8) -> 40 | J8: =SUMIFS(Children!$Q$13:$Q$128,Children!$B$13:$B$128,Families!A8) -> 15835 | K8: =MAX(0,IF(G8<CCBThreshold, IF(I8/H8<CCBMaxHours, I8*52*CCBHourlyRate, 50*52*CCBHourlyRate ), IF(I8/H8<50, I8*52*(CCBHourlyRate-(G8-CCBThreshold)*CCBThresholdModifier), 50*52*(CCBHourlyRate-(G8-CCBThreshold)*CCBThresholdModifier) ) )) -> 0 | L8: =MIN((J8-K8) * CCRRate, (CCRMax*H8)) -> 7613 | M8: =J8-(K8+L8) -> 8222
A9: caya-02 | B9: Caya | C9: Villette | D9: Caya | E9: Claude | F9: Lundqvist | G9: 147000 | H9: =COUNTIF(Children!$B$13:$B$128,A9) -> 1 | I9: =10*SUMIFS(Children!$K$13:$K$128,Children!$B$13:$B$128,Families!A9) -> 30 | J9: =SUMIFS(Children!$Q$13:$Q$128,Children!$B$13:$B$128,Families!A9) -> 14340 | K9: =MAX(0,IF(G9<CCBThreshold, IF(I9/H9<CCBMaxHours, I9*52*CCBHourlyRate, 50*52*CCBHourlyRate ), IF(I9/H9<50, I9*52*(CCBHourlyRate-(G9-CCBThreshold)*CCBThresholdModifier), 50*52*(CCBHourlyRate-(G9-CCBThreshold)*CCBThresholdModifier) ) )) -> 88.51596 | L9: =MIN((J9-K9) * CCRRate, (CCRMax*H9)) -> 7125.742 | M9: =J9-(K9+L9) -> 7125.742
A10: chien-03 | B10: Chien | C10: Hui | D10: Chien | E10: Kuan-Yin | F10: Burger | G10: 170713 | H10: =COUNTIF(Children!$B$13:$B$128,A10) -> 2 | I10: =10*SUMIFS(Children!$K$13:$K$128,Children!$B$13:$B$128,Families!A10) -> 80 | J10: =SUMIFS(Children!$Q$13:$Q$128,Children!$B$13:$B$128,Families!A10) -> 42115 | K10: =MAX(0,IF(G10<CCBThreshold, IF(I10/H10<CCBMaxHours, I10*52*CCBHourlyRate, 50*52*CCBHourlyRate ), IF(I10/H10<50, I10*52*(CCBHourlyRate-(G10-CCBThreshold)*CCBThresholdModifier), 50*52*(CCBHourlyRate-(G10-CCBThreshold)*CCBThresholdModifier) ) )) -> 0 | L10: =MIN((J10-K10) * CCRRate, (CCRMax*H10)) -> 15226 | M10: =J10-(K10+L10) -> 26889
A11: coburn-02 | B11: Coburn | C11: Hannah | D11: Coburn | E11: Cedric | F11: Coburn | G11: 165435 | H11: =COUNTIF(Children!$B$13:$B$128,A11) -> 2 | I11: =10*SUMIFS(Children!$K$13:$K$128,Children!$B$13:$B$128,Families!A11) -> 80 | J11: =SUMIFS(Children!$Q$13:$Q$128,Children!$B$13:$B$128,Families!A11) -> 47135 | K11: =MAX(0,IF(G11<CCBThreshold, IF(I11/H11<CCBMaxHours, I11*52*CCBHourlyRate, 50*52*CCBHourlyRate ), IF(I11/H11<50, I11*52*(CCBHourlyRate-(G11-CCBThreshold)*CCBThresholdModifier), 50*52*(CCBHourlyRate-(G11-CCBThreshold)*CCBThresholdModifier) ) )) -> 0 | L11: =MIN((J11-K11) * CCRRate, (CCRMax*H11)) -> 15226 | M11: =J11-(K11+L11) -> 31909
A12: course-01 | B12: Course | C12: Astolpho | D12: Course | E12: Clemence | F12: Course | G12: 118250 | H12: =COUNTIF(Children!$B$13:$B$128,A12) -> 1 | I12: =10*SUMIFS(Children!$K$13:$K$128,Children!$B$13:$B$128,Families!A12) -> 40 | J12: =SUMIFS(Children!$Q$13:$Q$128,Children!$B$13:$B$128,Families!A12) -> 17395 | K12: =MAX(0,IF(G12<CCBThreshold, IF(I12/H12<CCBMaxHours, I12*52*CCBHourlyRate, 50*52*CCBHourlyRate ), IF(I12/H12<50, I12*52*(CCBHourlyRate-(G12-CCBThreshold)*CCBThresholdModifier), 50*52*(CCBHourlyRate-(G12-CCBThreshold)*CCBThresholdModifier) ) )) -> 506.72128 | L12: =MIN((J12-K12) * CCRRate, (CCRMax*H12)) -> 7613 | M12: =J12-(K12+L12) -> 9275.2787
A13: crombie-03 | B13: Crombie | C13: Justin | D13: Crombie | E13: Janis | F13: Phillips | G13: 163683 | H13: =COUNTIF(Children!$B$13:$B$128,A13) -> 4 | I13: =10*SUMIFS(Children!$K$13:$K$128,Children!$B$13:$B$128,Families!A13) -> 200 | J13: =SUMIFS(Children!$Q$13:$Q$128,Children!$B$13:$B$128,Families!A13) -> 108350 | K13: =MAX(0,IF(G13<CCBThreshold, IF(I13/H13<CCBMaxHours, I13*52*CCBHourlyRate, 50*52*CCBHourlyRate ), IF(I13/H13<50, I13*52*(CCBHourlyRate-(G13-CCBThreshold)*CCBThresholdModifier), 50*52*(CCBHourlyRate-(G13-CCBThreshold)*CCBThresholdModifier) ) )) -> 0 | L13: =MIN((J13-K13) * CCRRate, (CCRMax*H13)) -> 30452 | M13: =J13-(K13+L13) -> 77898
A14: dastous-01 | B14: Dastous | C14: Fletcher | D14: Dastous | E14: Sabine | F14: Dastous | G14: 166400 | H14: =COUNTIF(Children!$B$13:$B$128,A14) -> 1 | I14: =10*SUMIFS(Children!$K$13:$K$128,Children!$B$13:$B$128,Families!A14) -> 50 | J14: =SUMIFS(Children!$Q$13:$Q$128,Children!$B$13:$B$128,Families!A14) -> 18695 | K14: =MAX(0,IF(G14<CCBThreshold, IF(I14/H14<CCBMaxHours, I14*52*CCBHourlyRate, 50*52*CCBHourlyRate ), IF(I14/H14<50, I14*52*(CCBHourlyRate-(G14-CCBThreshold)*CCBThresholdModifier), 50*52*(CCBHourlyRate-(G14-CCBThreshold)*CCBThresholdModifier) ) )) -> 0 | L14: =MIN((J14-K14) * CCRRate, (CCRMax*H14)) -> 7613 | M14: =J14-(K14+L14) -> 11082
A15: dorrington-01 | B15: Dorrington | C15: Jacob | D15: Dorrington | G15: 35533 | H15: =COUNTIF(Children!$B$13:$B$128,A15) -> 1 | I15: =10*SUMIFS(Children!$K$13:$K$128,Children!$B$13:$B$128,Families!A15) -> 10 | J15: =SUMIFS(Children!$Q$13:$Q$128,Children!$B$13:$B$128,Families!A15) -> 5070 | K15: =MAX(0,IF(G15<CCBThreshold, IF(I15/H15<CCBMaxHours, I15*52*CCBHourlyRate, 50*52*CCBHourlyRate ), IF(I15/H15<50, I15*52*(CCBHourlyRate-(G15-CCBThreshold)*CCBThresholdModifier), 50*52*(CCBHourlyRate-(G15-CCBThreshold)*CCBThresholdModifier) ) )) -> 373.88 | L15: =MIN((J15-K15) * CCRRate, (CCRMax*H15)) -> 2348.06 | M15: =J15-(K15+L15) -> 2348.06
A16: duggan-03 | B16: Duggan | C16: Jackson | D16: Duggan | E16: Marlene | F16: Duggan | G16: 172321 | H16: =COUNTIF(Children!$B$13:$B$128,A16) -> 4 | I16: =10*SUMIFS(Children!$K$13:$K$128,Children!$B$13:$B$128,Families!A16) -> 120 | J16: =SUMIFS(Children!$Q$13:$Q$128,Children!$B$13:$B$128,Families!A16) -> 68740 | K16: =MAX(0,IF(G16<CCBThreshold, IF(I16/H16<CCBMaxHours, I16*52*CCBHourlyRate, 50*52*CCBHourlyRate ), IF(I16/H16<50, I16*52*(CCBHourlyRate-(G16-CCBThreshold)*CCBThresholdModifier), 50*52*(CCBHourlyRate-(G16-CCBThreshold)*CCBThresholdModifier) ) )) -> 0 | L16: =MIN((J16-K16) * CCRRate, (CCRMax*H16)) -> 30452 | M16: =J16-(K16+L16) -> 38288
A17: dumaresq-03 | B17: Dumaresq | C17: Molly | D17: Dumaresq | F17: Erickson | G17: 137112 | H17: =COUNTIF(Children!$B$13:$B$128,A17) -> 1 | I17: =10*SUMIFS(Children!$K$13:$K$128,Children!$B$13:$B$128,Families!A17) -> 40 | J17: =SUMIFS(Children!$Q$13:$Q$128,Children!$B$13:$B$128,Families!A17) -> 15355 | K17: =MAX(0,IF(G17<CCBThreshold, IF(I17/H17<CCBMaxHours, I17*52*CCBHourlyRate, 50*52*CCBHourlyRate ), IF(I17/H17<50, I17*52*(CCBHourlyRate-(G17-CCBThreshold)*CCBThresholdModifier), 50*52*(CCBHourlyRate-(G17-CCBThreshold)*CCBThresholdModifier) ) )) -> 251.70704 | L17: =MIN((J17-K17) * CCRRate, (CCRMax*H17)) -> 7551.6465 | M17: =J17-(K17+L17) -> 7551.6465
A18: duranseau-01 | B18: Duranseau | C18: Fleurette | D18: Duranseau | E18: Arienne | F18: Dreher | G18: 142117 | H18: =COUNTIF(Children!$B$13:$B$128,A18) -> 1 | I18: =10*SUMIFS(Children!$K$13:$K$128,Children!$B$13:$B$128,Families!A18) -> 30 | J18: =SUMIFS(Children!$Q$13:$Q$128,Children!$B$13:$B$128,Families!A18) -> 12795 | K18: =MAX(0,IF(G18<CCBThreshold, IF(I18/H18<CCBMaxHours, I18*52*CCBHourlyRate, 50*52*CCBHourlyRate ), IF(I18/H18<50, I18*52*(CCBHourlyRate-(G18-CCBThreshold)*CCBThresholdModifier), 50*52*(CCBHourlyRate-(G18-CCBThreshold)*CCBThresholdModifier) ) )) -> 138.02958 | L18: =MIN((J18-K18) * CCRRate, (CCRMax*H18)) -> 6328.4852 | M18: =J18-(K18+L18) -> 6328.4852
A19: eatock-01 | B19: Eatock | C19: Charlotte | D19: Eatock | E19: Robert | F19: Eatock | G19: 76982 | H19: =COUNTIF(Children!$B$13:$B$128,A19) -> 2 | I19: =10*SUMIFS(Children!$K$13:$K$128,Children!$B$13:$B$128,Families!A19) -> 60 | J19: =SUMIFS(Children!$Q$13:$Q$128,Children!$B$13:$B$128,Families!A19) -> 23375 | K19: =MAX(0,IF(G19<CCBThreshold, IF(I19/H19<CCBMaxHours, I19*52*CCBHourlyRate, 50*52*CCBHourlyRate ), IF(I19/H19<50, I19*52*(CCBHourlyRate-(G19-CCBThreshold)*CCBThresholdModifier), 50*52*(CCBHourlyRate-(G19-CCBThreshold)*CCBThresholdModifier) ) )) -> 1596.997 | L19: =MIN((J19-K19) * CCRRate, (CCRMax*H19)) -> 10889.002 | M19: =J19-(K19+L19) -> 10889.002
A20: edgerton-01 | B20: Edgerton | C20: Kiara | D20: Edgerton | G20: 69888 | H20: =COUNTIF(Children!$B$13:$B$128,A20) -> 1 | I20: =10*SUMIFS(Children!$K$13:$K$128,Children!$B$13:$B$128,Families!A20) -> 10 | J20: =SUMIFS(Children!$Q$13:$Q$128,Children!$B$13:$B$128,Families!A20) -> 4310 | K20: =MAX(0,IF(G20<CCBThreshold, IF(I20/H20<CCBMaxHours, I20*52*CCBHourlyRate, 50*52*CCBHourlyRate ), IF(I20/H20<50, I20*52*(CCBHourlyRate-(G20-CCBThreshold)*CCBThresholdModifier), 50*52*(CCBHourlyRate-(G20-CCBThreshold)*CCBThresholdModifier) ) )) -> 290.14388 | L20: =MIN((J20-K20) * CCRRate, (CCRMax*H20)) -> 2009.9281 | M20: =J20-(K20+L20) -> 2009.9281
A21: fantl-02 | B21: Fantl | C21: Natasha | D21: Fantl | G21: 50642 | H21: =COUNTIF(Children!$B$13:$B$128,A21) -> 2 | I21: =10*SUMIFS(Children!$K$13:$K$128,Children!$B$13:$B$128,Families!A21) -> 60 | J21: =SUMIFS(Children!$Q$13:$Q$128,Children!$B$13:$B$128,Families!A21) -> 38000 | K21: =MAX(0,IF(G21<CCBThreshold, IF(I21/H21<CCBMaxHours, I21*52*CCBHourlyRate, 50*52*CCBHourlyRate ), IF(I21/H21<50, I21*52*(CCBHourlyRate-(G21-CCBThreshold)*CCBThresholdModifier), 50*52*(CCBHourlyRate-(G21-CCBThreshold)*CCBThresholdModifier) ) )) -> 2131.1722 | L21: =MIN((J21-K21) * CCRRate, (CCRMax*H21)) -> 15226 | M21: =J21-(K21+L21) -> 20642.828
A22: farquhar-03 | B22: Farquhar | C22: Margaret | D22: Farquhar | E22: Billy | F22: Farquhar | G22: 101239 | H22: =COUNTIF(Children!$B$13:$B$128,A22) -> 2 | I22: =10*SUMIFS(Children!$K$13:$K$128,Children!$B$13:$B$128,Families!A22) -> 60 | J22: =SUMIFS(Children!$Q$13:$Q$128,Children!$B$13:$B$128,Families!A22) -> 26960 | K22: =MAX(0,IF(G22<CCBThreshold, IF(I22/H22<CCBMaxHours, I22*52*CCBHourlyRate, 50*52*CCBHourlyRate ), IF(I22/H22<50, I22*52*(CCBHourlyRate-(G22-CCBThreshold)*CCBThresholdModifier), 50*52*(CCBHourlyRate-(G22-CCBThreshold)*CCBThresholdModifier) ) )) -> 1105.065 | L22: =MIN((J22-K22) * CCRRate, (CCRMax*H22)) -> 12927.468 | M22: =J22-(K22+L22) -> 12927.467
A23: fichter-02 | B23: Fichter | C23: Billy | D23: Fichter | E23: Peggy | F23: Fichter | G23: 164844 | H23: =COUNTIF(Children!$B$13:$B$128,A23) -> 3 | I23: =10*SUMIFS(Children!$K$13:$K$128,Children!$B$13:$B$128,Families!A23) -> 120 | J23: =SUMIFS(Children!$Q$13:$Q$128,Children!$B$13:$B$128,Families!A23) -> 63385 | K23: =MAX(0,IF(G23<CCBThreshold, IF(I23/H23<CCBMaxHours, I23*52*CCBHourlyRate, 50*52*CCBHourlyRate ), IF(I23/H23<50, I23*52*(CCBHourlyRate-(G23-CCBThreshold)*CCBThresholdModifier), 50*52*(CCBHourlyRate-(G23-CCBThreshold)*CCBThresholdModifier) ) )) -> 0 | L23: =MIN((J23-K23) * CCRRate, (CCRMax*H23)) -> 22839 | M23: =J23-(K23+L23) -> 40546
A24: gallegos-03 | B24: Gallegos | C24: Bertha | D24: Gallegos | E24: Saville | F24: Gallegos | G24: 180224 | H24: =COUNTIF(Children!$B$13:$B$128,A24) -> 2 | I24: =10*SUMIFS(Children!$K$13:$K$128,Children!$B$13:$B$128,Families!A24) -> 80 | J24: =SUMIFS(Children!$Q$13:$Q$128,Children!$B$13:$B$128,Families!A24) -> 34980 | K24: =MAX(0,IF(G24<CCBThreshold, IF(I24/H24<CCBMaxHours, I24*52*CCBHourlyRate, 50*52*CCBHourlyRate ), IF(I24/H24<50, I24*52*(CCBHourlyRate-(G24-CCBThreshold)*CCBThresholdModifier), 50*52*(CCBHourlyRate-(G24-CCBThreshold)*CCBThresholdModifier) ) )) -> 0 | L24: =MIN((J24-K24) * CCRRate, (CCRMax*H24)) -> 15226 | M24: =J24-(K24+L24) -> 19754
A25: gallop-03 | B25: Gallop | C25: Annabelle | D25: Gallop | G25: 60884 | H25: =COUNTIF(Children!$B$13:$B$128,A25) -> 2 | I25: =10*SUMIFS(Children!$K$13:$K$128,Children!$B$13:$B$128,Families!A25) -> 80 | J25: =SUMIFS(Children!$Q$13:$Q$128,Children!$B$13:$B$128,Families!A25) -> 37945 | K25: =MAX(0,IF(G25<CCBThreshold, IF(I25/H25<CCBMaxHours, I25*52*CCBHourlyRate, 50*52*CCBHourlyRate ), IF(I25/H25<50, I25*52*(CCBHourlyRate-(G25-CCBThreshold)*CCBThresholdModifier), 50*52*(CCBHourlyRate-(G25-CCBThreshold)*CCBThresholdModifier) ) )) -> 2564.6192 | L25: =MIN((J25-K25) * CCRRate, (CCRMax*H25)) -> 15226 | M25: =J25-(K25+L25) -> 20154.381
